<?xml version="1.0" encoding="UTF-8"?>
<!-- Generated by org.testng.reporters.JUnitReportReporter -->
<testsuite hostname="MSI" failures="0" tests="6" name="com.TestNGdemo.TestNGparameter1" time="0.037" errors="1" timestamp="2022-10-06T12:30:09 IST" skipped="0">
  <testcase classname="com.TestNGdemo.TestNGparameter1" name="m2" time="0.002"/>
  <system-out/>
  <testcase classname="com.TestNGdemo.TestNGparameter1" name="m1" time="0.023">
    <error message="
Method TestNGparameter1.m1()[pri:0, instance:com.TestNGdemo.TestNGparameter1@5fa07e12] should have thrown an exception of type class java.lang.ArithmeticException" type="org.testng.TestException">
      <![CDATA[org.testng.TestException: 
Method TestNGparameter1.m1()[pri:0, instance:com.TestNGdemo.TestNGparameter1@5fa07e12] should have thrown an exception of type class java.lang.ArithmeticException
at org.testng.internal.ExpectedExceptionsHolder.noException(ExpectedExceptionsHolder.java:82)
at org.testng.internal.TestInvoker.considerExceptions(TestInvoker.java:741)
at org.testng.internal.TestInvoker.invokeMethod(TestInvoker.java:629)
at org.testng.internal.TestInvoker.invokeTestMethod(TestInvoker.java:173)
at org.testng.internal.MethodRunner.runInSequence(MethodRunner.java:46)
at org.testng.internal.TestInvoker$MethodInvocationAgent.invoke(TestInvoker.java:816)
at org.testng.internal.TestInvoker.invokeTestMethods(TestInvoker.java:146)
at org.testng.internal.TestMethodWorker.invokeTestMethods(TestMethodWorker.java:146)
at org.testng.internal.TestMethodWorker.run(TestMethodWorker.java:128)
at java.base/java.util.ArrayList.forEach(ArrayList.java:1511)
at org.testng.TestRunner.privateRun(TestRunner.java:766)
at org.testng.TestRunner.run(TestRunner.java:587)
at org.testng.SuiteRunner.runTest(SuiteRunner.java:384)
at org.testng.SuiteRunner.runSequentially(SuiteRunner.java:378)
at org.testng.SuiteRunner.privateRun(SuiteRunner.java:337)
at org.testng.SuiteRunner.run(SuiteRunner.java:286)
at org.testng.SuiteRunnerWorker.runSuite(SuiteRunnerWorker.java:53)
at org.testng.SuiteRunnerWorker.run(SuiteRunnerWorker.java:96)
at org.testng.TestNG.runSuitesSequentially(TestNG.java:1187)
at org.testng.TestNG.runSuitesLocally(TestNG.java:1109)
at org.testng.TestNG.runSuites(TestNG.java:1039)
at org.testng.TestNG.run(TestNG.java:1007)
at org.testng.remote.AbstractRemoteTestNG.run(AbstractRemoteTestNG.java:115)
at org.testng.remote.RemoteTestNG.initAndRun(RemoteTestNG.java:251)
at org.testng.remote.RemoteTestNG.main(RemoteTestNG.java:77)
]]>
    </error>
  </testcase> <!-- m1 -->
  <system-out/>
  <testcase classname="com.TestNGdemo.TestNGparameter1" name="m5" time="0.003"/>
  <system-out/>
  <testcase classname="com.TestNGdemo.TestNGparameter1" name="m3" time="0.007"/>
  <system-out/>
  <testcase classname="com.TestNGdemo.TestNGparameter1" name="m4" time="0.001"/>
  <system-out/>
  <testcase classname="com.TestNGdemo.TestNGparameter1" name="m6" time="0.001"/>
  <system-out/>
</testsuite> <!-- com.TestNGdemo.TestNGparameter1 -->
